Workbook

Sheet 📖 Como usar
B1: 📖 COMO USAR ESTA PLANILHA
B3: PASSO 1 — ABA 📥 RECEITAS
B4: PASSO 2 — ABA 📤 DESPESAS
B5: PASSO 3 — ABA 🔴 DÍVIDAS
B6: PASSO 4 — ABA 🌟 METAS
B7: PASSO 5 — ABA 📊 PAINEL
B8: → Acompanhe o resumo automático. O painel calcula tudo para você.
B9: 💡 DICA DO ADRIANO:
B10: → Use a Regra 50-30-20: 50% para necessidades, 30% para desejos e 20% para poupança/investimentos.
B11: ⚠️ IMPORTANTE:
B12: → Textos em AZUL = campos que você deve preencher. Textos em PRETO = fórmulas automáticas, não edite.
B13: 📲 SIGA NO INSTAGRAM:
... B16: → Com 3 meses de uso consistente, você terá clareza total das suas finanças e uma meta de investimento realista.

Sheet 📊 Painel
B1: 💰 CONTROLE FINANCEIRO PESSOAL
B2: por Adriano Santos | Planejador Financeiro @adrianosantos_pf
B4: Mês de referência: | D4: June 2026
B6: 💚 Total Receitas | D6: 🔴 Total Despesas | F6: ⭐ Saldo do Mês
B7: ='📥 Receitas'!C30 -> 15800 | D7: ='📤 Despesas'!C50 -> 2580 | F7: =B7-D7 -> 13220
B9: 📋 RESUMO POR CATEGORIA
B10: Categoria | C10: Orçado (R$) | D10: Gasto (R$) | E10: Saldo (R$) | F10: % do Total | G10: Status
B11: 🏠 Moradia | C11: 2500 | D11: =SUM('📤 Despesas'!C7:C11) -> 1580 | E11: =C11-D11 -> 920 | F11: =IF(D11=0,0,D11/'📤 Despesas'!C50) -> 0.6124031 | G11: =IF(E11>=0,"✅ OK","⚠️ Excedeu") -> ✅ OK
B12: 🍽️ Alimentação | C12: 1200 | D12: =SUM('📤 Despesas'!C13:C17) -> 0 | E12: =C12-D12 -> 1200 | F12: =IF(D12=0,0,D12/'📤 Despesas'!C50) -> 0 | G12: =IF(E12>=0,"✅ OK","⚠️ Excedeu") -> ✅ OK
B13: 🚗 Transporte | C13: 800 | D13: =SUM('📤 Despesas'!C19:C23) -> 0 | E13: =C13-D13 -> 800 | F13: =IF(D13=0,0,D13/'📤 Despesas'!C50) -> 0 | G13: =IF(E13>=0,"✅ OK","⚠️ Excedeu") -> ✅ OK
B14: 💊 Saúde | C14: 500 | D14: =SUM('📤 Despesas'!C25:C29) -> 0 | E14: =C14-D14 -> 500 | F14: =IF(D14=0,0,D14/'📤 Despesas'!C50) -> 0 | G14: =IF(E14>=0,"✅ OK","⚠️ Excedeu") -> ✅ OK
B15: 📚 Educação | C15: 400 | D15: =SUM('📤 Despesas'!C31:C35) -> 0 | E15: =C15-D15 -> 400 | F15: =IF(D15=0,0,D15/'📤 Despesas'!C50) -> 0 | G15: =IF(E15>=0,"✅ OK","⚠️ Excedeu") -> ✅ OK
B16: 🎭 Lazer | C16: 300 | D16: =SUM('📤 Despesas'!C37:C41) -> 0 | E16: =C16-D16 -> 300 | F16: =IF(D16=0,0,D16/'📤 Despesas'!C50) -> 0 | G16: =IF(E16>=0,"✅ OK","⚠️ Excedeu") -> ✅ OK
B17: 💳 Dívidas | C17: 600 | D17: =SUM('📤 Despesas'!C43:C47) -> 1000 | E17: =C17-D17 -> -400 | F17: =IF(D17=0,0,D17/'📤 Despesas'!C50) -> 0.3875969 | G17: =IF(E17>=0,"✅ OK","⚠️ Excedeu") -> ⚠️ Excedeu
B18: 💰 Investimentos | C18: 500 | D18: ='📥 Receitas'!C35 -> 0 | E18: =C18-D18 -> 500 | F18: =IF(D18=0,0,D18/'📤 Despesas'!C50) -> 0 | G18: =IF(E18>=0,"✅ OK","⚠️ Excedeu") -> ✅ OK
B19: 📦 Outros | C19: 200 | D19: =SUM('📤 Despesas'!C49,'📤 Despesas'!C51:C53) -> 0 | E19: =C19-D19 -> 200 | F19: =IF(D19=0,0,D19/'📤 Despesas'!C50) -> 0 | G19: =IF(E19>=0,"✅ OK","⚠️ Excedeu") -> ✅ OK
B20: TOTAL | C20: =SUM(C11:C19) -> 7000 | D20: =SUM(D11:D19) -> 2580 | E20: =SUM(E11:E19) -> 4420 | F20: 100%
B22: 🎯 META DE POUPANÇA E INVESTIMENTO
C23: Meta mensal de poupança (R$): | D23: 1000
C24: Já poupado este mês (R$): | D24: ='📥 Receitas'!C35 -> 0
C25: Falta poupar (R$): | D25: =D23-D24 -> 1000
C26: % da meta atingida: | D26: =IF(D23=0,0,D24/D23) -> 0
B28: 💡 REGRA 50-30-20: 50% necessidades | 30% desejos | 20% poupança/investimentos

Sheet 📥 Receitas
B1: 📥 REGISTRO DE RECEITAS
B2: Registre todas as entradas de dinheiro — salário, freelas, aluguéis, etc.
B4: Descrição da Receita | C4: Valor (R$) | D4: Data | E4: Observação
B5: Salário principal | C5: 5000 | D5: 01/06/2025 | E5: Empresa X
B6: Freela / Renda extra | C6: 800 | D6: 10/06/2025 | E6: Projeto Y
B7: Aluguel recebido
B8: Dividendos / Investimentos
B9: Comissões / Bonificações | C9: 10000
B10: Outros rendimentos
B30: TOTAL RECEITAS | C30: =SUM(C5:C28) -> 15800
B34: 💰 Reserva / Investimento
C35: 0 | D35: ← digite quanto investiu/poupou este mês

Sheet 📤 Despesas
B1: 📤 REGISTRO DE DESPESAS
B2: Anote cada gasto — pequenos gastos ignorados destroem o orçamento!
B6: 🏠 MORADIA | C6: Valor (R$) | D6: Data | E6: Observação
B7: Aluguel / Prestação | C7: 1000
B8: Condomínio | C8: 400
B9: Água/Luz/Gás | C9: 80
B10: Internet/Telefone | C10: 100
B11: IPTU/Seguros
B12: 🍽️ ALIMENTAÇÃO | C12: Valor (R$) | D12: Data | E12: Observação
B13: Supermercado
B14: Feira/Hortifruti
B15: Restaurantes/iFood
B16: Padaria / Lanches
B17: Outros alimentos
B18: 🚗 TRANSPORTE | C18: Valor (R$) | D18: Data | E18: Observação
B19: Combustível
B20: Uber/Táxi/Transporte
B21: Prestação carro/moto
B22: IPVA/Seguro auto
B23: Manutenção
B24: 💊 SAÚDE | C24: Valor (R$) | D24: Data | E24: Observação
B25: Plano de saúde
B26: Medicamentos
B27: Consultas/Exames
B28: Academia/Esportes
B29: Outros saúde
B30: 📚 EDUCAÇÃO | C30: Valor (R$) | D30: Data | E30: Observação
B31: Cursos e treinamentos
B32: Livros / Materiais
B33: Escola filhos
B34: Plataformas online
B35: Outros educação
B36: 🎭 LAZER | C36: Valor (R$) | D36: Data | E36: Observação
B37: Streaming (Netflix etc.)
B38: Saídas/Passeios
B39: Assinaturas diversas
B40: Presentes
B41: Outros lazer
B42: 💳 DÍVIDAS | C42: Valor (R$) | D42: Data | E42: Observação
B43: Cartão de crédito | C43: 1000
...

Sheet 🔴 Dívidas
B1: 🔴 MAPA DE DÍVIDAS — Saia do vermelho com método!
B2: Liste todas as dívidas. Use o Método Bola de Neve: quite a menor primeiro e use a parcela liberada na próxima.
B4: Credor / Dívida | C4: Saldo Total (R$) | D4: Parcela (R$) | E4: Juros % a.m. | F4: Parcelas Rest. | G4: Vencimento | H4: Prioridade
B5: Cartão de crédito X | C5: 3200 | D5: 320 | E5: 12.5 | F5: 10 | G5: 10/mês | H5: 1ª - Urgente
B6: Empréstimo pessoal | C6: 8000 | D6: 500 | E6: 3.2 | F6: 16 | G6: 15/mês | H6: 2ª
B7: Financiamento carro | C7: 25000 | D7: 850 | E7: 1.4 | F7: 30 | G7: 20/mês | H7: 3ª
B14: TOTAL EM DÍVIDAS | C14: =SUM(C5:C12) -> 36200
B16: 📌 MÉTODO BOLA DE NEVE: Quite a menor dívida primeiro → use a parcela liberada para atacar a próxima
B17: 🔥 MÉTODO AVALANCHE: Quite a de maior juros primeiro → paga menos juros no total

Sheet 🌟 Metas e Sonhos
B1: 🌟 METAS FINANCEIRAS E SONHOS
B2: Sonhos sem data são só desejos. Coloque valor e prazo em cada meta!
B4: Sonho / Meta | C4: Valor Total (R$) | D4: Já poupei (R$) | E4: Falta (R$) | F4: Prazo (meses) | G4: Poupar/mês (R$)
B5: 🚗 Carro novo / quitação | C5: 40000 | D5: 5000 | E5: =IF(C5=0,"",C5-D5) -> 35000 | F5: 12 | G5: =IF(F5=0,"",E5/F5) -> 2916.6667
B6: 🏠 Entrada do imóvel | C6: 80000 | D6: 10000 | E6: =IF(C6=0,"",C6-D6) -> 70000 | F6: 12 | G6: =IF(F6=0,"",E6/F6) -> 5833.3333
B7: 📚 Curso / Pós-graduação | C7: 8000 | D7: 1200 | E7: =IF(C7=0,"",C7-D7) -> 6800 | F7: 12 | G7: =IF(F7=0,"",E7/F7) -> 566.66667
B8: ✈️ Viagem dos sonhos | C8: 12000 | D8: 2000 | E8: =IF(C8=0,"",C8-D8) -> 10000 | F8: 12 | G8: =IF(F8=0,"",E8/F8) -> 833.33333
B9: 💼 Reserva de emergência (6x salário) | C9: 30000 | D9: 8000 | E9: =IF(C9=0,"",C9-D9) -> 22000 | F9: 12 | G9: =IF(F9=0,"",E9/F9) -> 1833.3333
E10: =IF(C10=0,"",C10-D10) | G10: =IF(F10=0,"",E10/F10)
E11: =IF(C11=0,"",C11-D11) | G11: =IF(F11=0,"",E11/F11)
E12: =IF(C12=0,"",C12-D12) | G12: =IF(F12=0,"",E12/F12)
